python3: can't open file 'semantic-labeling-arabic/server/manage.py': [Errno 2] No such file or directory
Exception ignored in thread started by: <function check_errors.<locals>.wrapper at 0x7fd35f5b7af0>
Traceback (most recent call last):
  File "/home/nareed/venv/lib/python3.8/site-packages/django/utils/autoreload.py", line 225, in wrapper
    fn(*args, **kwargs)
  File "/home/nareed/venv/lib/python3.8/site-packages/django/core/management/commands/runserver.py", line 120, in inner_run
    self.check(display_num_errors=True)
  File "/home/nareed/venv/lib/python3.8/site-packages/django/core/management/base.py", line 361, in check
    all_issues = self._run_checks(
  File "/home/nareed/venv/lib/python3.8/site-packages/django/core/management/base.py", line 351, in _run_checks
    return checks.run_checks(**kwargs)
  File "/home/nareed/venv/lib/python3.8/site-packages/django/core/checks/registry.py", line 73, in run_checks
    new_errors = check(app_configs=app_configs)
  File "/home/nareed/venv/lib/python3.8/site-packages/django/core/checks/urls.py", line 13, in check_url_config
    return check_resolver(resolver)
  File "/home/nareed/venv/lib/python3.8/site-packages/django/core/checks/urls.py", line 23, in check_resolver
    return check_method()
  File "/home/nareed/venv/lib/python3.8/site-packages/django/urls/resolvers.py", line 397, in check
    for pattern in self.url_patterns:
  File "/home/nareed/venv/lib/python3.8/site-packages/django/utils/functional.py", line 36, in __get__
    res = instance.__dict__[self.name] = self.func(instance)
  File "/home/nareed/venv/lib/python3.8/site-packages/django/urls/resolvers.py", line 536, in url_patterns
    patterns = getattr(self.urlconf_module, "urlpatterns", self.urlconf_module)
  File "/home/nareed/venv/lib/python3.8/site-packages/django/utils/functional.py", line 36, in __get__
    res = instance.__dict__[self.name] = self.func(instance)
  File "/home/nareed/venv/lib/python3.8/site-packages/django/urls/resolvers.py", line 529, in urlconf_module
    return import_module(self.urlconf_name)
  File "/usr/lib/python3.8/importlib/__init__.py", line 127, in import_module
    return _bootstrap._gcd_import(name[level:], package, level)
  File "<frozen importlib._bootstrap>", line 1014, in _gcd_import
  File "<frozen importlib._bootstrap>", line 991, in _find_and_load
  File "<frozen importlib._bootstrap>", line 975, in _find_and_load_unlocked
  File "<frozen importlib._bootstrap>", line 671, in _load_unlocked
  File "<frozen importlib._bootstrap_external>", line 783, in exec_module
  File "<frozen importlib._bootstrap>", line 219, in _call_with_frames_removed
  File "/home/nareed/semantic-labeling-arabic/server/server/urls.py", line 21, in <module>
    path('', include('term_labeling.urls')),
  File "/home/nareed/venv/lib/python3.8/site-packages/django/urls/conf.py", line 34, in include
    urlconf_module = import_module(urlconf_module)
  File "/usr/lib/python3.8/importlib/__init__.py", line 127, in import_module
    return _bootstrap._gcd_import(name[level:], package, level)
  File "<frozen importlib._bootstrap>", line 1014, in _gcd_import
  File "<frozen importlib._bootstrap>", line 991, in _find_and_load
  File "<frozen importlib._bootstrap>", line 975, in _find_and_load_unlocked
  File "<frozen importlib._bootstrap>", line 671, in _load_unlocked
  File "<frozen importlib._bootstrap_external>", line 783, in exec_module
  File "<frozen importlib._bootstrap>", line 219, in _call_with_frames_removed
  File "/home/nareed/semantic-labeling-arabic/server/term_labeling/urls.py", line 4, in <module>
    from . import views
SyntaxError: invalid syntax (views.py, line 63)
Performing system checks...

[2020-12-16 11:42:20,173 - DEBUG]: perform system check...
[2020-12-16 11:42:20,173 - DEBUG]: check java version...
[2020-12-16 11:42:20,295 - DEBUG]: Your java version is 11.0 which is compatiple with Farasa 
[2020-12-16 11:42:20,296 - DEBUG]: check toolkit binaries...
[2020-12-16 11:42:20,296 - INFO]: Dependencies seem to be satisfied..
[2020-12-16 11:42:20,296 - WARNING]: Be careful with large lines as they may break on interactive mode. You may switch to Standalone mode for such cases.
[2020-12-16 11:42:20,296 - INFO]: [37minitializing [STEM] task in [32mINTERACTIVE [37mmode...
[2020-12-16 11:42:29,703 - INFO]: task [STEM] is initialized interactively.
